<?xml version="1.0"?>
<robot xmlns:xacro="http://www.ros.org/wiki/xacro" name="dual_panda">
  <link name="world" />
  <link name="dual_arm_base_link" />

  <joint name="world_joint" type="fixed">
    <parent link="world" />
    <child link="dual_arm_base_link" />
    <origin xyz="0 0 0" rpy="0 0 0" />
  </joint>

  <xacro:macro name="panda_arm" params="prefix parent xyz rpy">
    <joint name="${prefix}base_joint" type="fixed">
      <parent link="${parent}" />
      <child link="${prefix}link0" />
      <origin xyz="${xyz}" rpy="${rpy}" />
    </joint>

    <link name="${prefix}link0">
      <visual>
        <geometry>
          <mesh filename="package://moveit_resources_panda_description/meshes/visual/link0.dae" />
        </geometry>
      </visual>
      <collision>
        <geometry>
          <mesh filename="package://moveit_resources_panda_description/meshes/collision/link0.stl" />
        </geometry>
      </collision>
    </link>

    <link name="${prefix}link1">
      <visual>
        <geometry>
          <mesh filename="package://moveit_resources_panda_description/meshes/visual/link1.dae" />
        </geometry>
      </visual>
      <collision>
        <geometry>
          <mesh filename="package://moveit_resources_panda_description/meshes/collision/link1.stl" />
        </geometry>
      </collision>
    </link>
    <joint name="${prefix}joint1" type="revolute">
      <safety_controller k_position="100.0" k_velocity="40.0" soft_lower_limit="-2.8973" soft_upper_limit="2.8973" />
      <origin rpy="0 0 0" xyz="0 0 0.333" />
      <parent link="${prefix}link0" />
      <child link="${prefix}link1" />
      <axis xyz="0 0 1" />
      <limit effort="87" lower="-2.9671" upper="2.9671" velocity="2.3925" />
    </joint>

    <link name="${prefix}link2">
      <visual>
        <geometry>
          <mesh filename="package://moveit_resources_panda_description/meshes/visual/link2.dae" />
        </geometry>
      </visual>
      <collision>
        <geometry>
          <mesh filename="package://moveit_resources_panda_description/meshes/collision/link2.stl" />
        </geometry>
      </collision>
    </link>
    <joint name="${prefix}joint2" type="revolute">
      <safety_controller k_position="100.0" k_velocity="40.0" soft_lower_limit="-1.7628" soft_upper_limit="1.7628" />
      <origin rpy="-1.57079632679 0 0" xyz="0 0 0" />
      <parent link="${prefix}link1" />
      <child link="${prefix}link2" />
      <axis xyz="0 0 1" />
      <limit effort="87" lower="-1.8326" upper="1.8326" velocity="2.3925" />
    </joint>

    <link name="${prefix}link3">
      <visual>
        <geometry>
          <mesh filename="package://moveit_resources_panda_description/meshes/visual/link3.dae" />
        </geometry>
      </visual>
      <collision>
        <geometry>
          <mesh filename="package://moveit_resources_panda_description/meshes/collision/link3.stl" />
        </geometry>
      </collision>
    </link>
    <joint name="${prefix}joint3" type="revolute">
      <safety_controller k_position="100.0" k_velocity="40.0" soft_lower_limit="-2.8973" soft_upper_limit="2.8973" />
      <origin rpy="1.57079632679 0 0" xyz="0 -0.316 0" />
      <parent link="${prefix}link2" />
      <child link="${prefix}link3" />
      <axis xyz="0 0 1" />
      <limit effort="87" lower="-2.9671" upper="2.9671" velocity="2.3925" />
    </joint>

    <link name="${prefix}link4">
      <visual>
        <geometry>
          <mesh filename="package://moveit_resources_panda_description/meshes/visual/link4.dae" />
        </geometry>
      </visual>
      <collision>
        <geometry>
          <mesh filename="package://moveit_resources_panda_description/meshes/collision/link4.stl" />
        </geometry>
      </collision>
    </link>
    <joint name="${prefix}joint4" type="revolute">
      <safety_controller k_position="100.0" k_velocity="40.0" soft_lower_limit="-3.0718" soft_upper_limit="0.0175" />
      <origin rpy="1.57079632679 0 0" xyz="0.0825 0 0" />
      <parent link="${prefix}link3" />
      <child link="${prefix}link4" />
      <axis xyz="0 0 1" />
      <limit effort="87" lower="-3.1416" upper="0.0873" velocity="2.3925" />
    </joint>

    <link name="${prefix}link5">
      <visual>
        <geometry>
          <mesh filename="package://moveit_resources_panda_description/meshes/visual/link5.dae" />
        </geometry>
      </visual>
      <collision>
        <geometry>
          <mesh filename="package://moveit_resources_panda_description/meshes/collision/link5.stl" />
        </geometry>
      </collision>
    </link>
    <joint name="${prefix}joint5" type="revolute">
      <safety_controller k_position="100.0" k_velocity="40.0" soft_lower_limit="-2.8973" soft_upper_limit="2.8973" />
      <origin rpy="-1.57079632679 0 0" xyz="-0.0825 0.384 0" />
      <parent link="${prefix}link4" />
      <child link="${prefix}link5" />
      <axis xyz="0 0 1" />
      <limit effort="12" lower="-2.9671" upper="2.9671" velocity="2.8710" />
    </joint>

    <link name="${prefix}link6">
      <visual>
        <geometry>
          <mesh filename="package://moveit_resources_panda_description/meshes/visual/link6.dae" />
        </geometry>
      </visual>
      <collision>
        <geometry>
          <mesh filename="package://moveit_resources_panda_description/meshes/collision/link6.stl" />
        </geometry>
      </collision>
    </link>
    <joint name="${prefix}joint6" type="revolute">
      <safety_controller k_position="100.0" k_velocity="40.0" soft_lower_limit="-0.0175" soft_upper_limit="3.7525" />
      <origin rpy="1.57079632679 0 0" xyz="0 0 0" />
      <parent link="${prefix}link5" />
      <child link="${prefix}link6" />
      <axis xyz="0 0 1" />
      <limit effort="12" lower="-0.0873" upper="3.8223" velocity="2.8710" />
    </joint>

    <link name="${prefix}link7">
      <visual>
        <geometry>
          <mesh filename="package://moveit_resources_panda_description/meshes/visual/link7.dae" />
        </geometry>
      </visual>
      <collision>
        <geometry>
          <mesh filename="package://moveit_resources_panda_description/meshes/collision/link7.stl" />
        </geometry>
      </collision>
    </link>
    <joint name="${prefix}joint7" type="revolute">
      <safety_controller k_position="100.0" k_velocity="40.0" soft_lower_limit="-2.8973" soft_upper_limit="2.8973" />
      <origin rpy="1.57079632679 0 0" xyz="0.088 0 0" />
      <parent link="${prefix}link6" />
      <child link="${prefix}link7" />
      <axis xyz="0 0 1" />
      <limit effort="12" lower="-2.9671" upper="2.9671" velocity="2.8710" />
    </joint>

    <link name="${prefix}link8" />
    <joint name="${prefix}joint8" type="fixed">
      <origin rpy="0 0 0" xyz="0 0 0.107" />
      <parent link="${prefix}link7" />
      <child link="${prefix}link8" />
    </joint>

    <link name="${prefix}hand">
      <visual>
        <geometry>
          <mesh filename="package://moveit_resources_panda_description/meshes/visual/hand.dae" />
        </geometry>
      </visual>
      <collision>
        <geometry>
          <mesh filename="package://moveit_resources_panda_description/meshes/collision/hand.stl" />
        </geometry>
      </collision>
    </link>
    <joint name="${prefix}hand_joint" type="fixed">
      <parent link="${prefix}link8" />
      <child link="${prefix}hand" />
      <origin rpy="0 0 -0.785398163397" xyz="0 0 0" />
    </joint>

    <link name="${prefix}leftfinger">
      <visual>
        <geometry>
          <mesh filename="package://moveit_resources_panda_description/meshes/visual/finger.dae" />
        </geometry>
      </visual>
      <collision>
        <geometry>
          <mesh filename="package://moveit_resources_panda_description/meshes/collision/finger.stl" />
        </geometry>
      </collision>
    </link>
    <joint name="${prefix}finger_joint1" type="prismatic">
      <parent link="${prefix}hand" />
      <child link="${prefix}leftfinger" />
      <origin rpy="0 0 0" xyz="0 0 0.0584" />
      <axis xyz="0 1 0" />
      <limit effort="20" lower="0.0" upper="0.04" velocity="0.2" />
    </joint>

    <link name="${prefix}rightfinger">
      <visual>
        <origin rpy="0 0 3.14159265359" xyz="0 0 0" />
        <geometry>
          <mesh filename="package://moveit_resources_panda_description/meshes/visual/finger.dae" />
        </geometry>
      </visual>
      <collision>
        <origin rpy="0 0 3.14159265359" xyz="0 0 0" />
        <geometry>
          <mesh filename="package://moveit_resources_panda_description/meshes/collision/finger.stl" />
        </geometry>
      </collision>
    </link>
    <joint name="${prefix}finger_joint2" type="prismatic">
      <parent link="${prefix}hand" />
      <child link="${prefix}rightfinger" />
      <origin rpy="0 0 0" xyz="0 0 0.0584" />
      <axis xyz="0 -1 0" />
      <limit effort="20" lower="0.0" upper="0.04" velocity="0.2" />
      <mimic joint="${prefix}finger_joint1" />
    </joint>
  </xacro:macro>

  <xacro:panda_arm prefix="left_panda_" parent="dual_arm_base_link" xyz="-0.35 0.18 0.0" rpy="0 0 0" />
  <xacro:panda_arm prefix="right_panda_" parent="dual_arm_base_link" xyz="0.35 -0.18 0.0" rpy="0 0 ${pi}" />
</robot>
